Workbook

Sheet Scan to Sheets
A1: Fecha | B1: Hora | C1: Codigo | D1: Cantidad

Sheet Cod_Gen
A1: Items | B1: Codigo | C1: Tipo de Equipo | D1: Marca | E1: Modelo | F1: N* Serie | G1: Categoria | H1: Cantidad Total
A2: 1 | B2: =UPPER(LEFT(C2,2)&LEFT(D2,2)&LEFT(E2,3)) -> ATHEMS5 | C2: ATRILES MICROFONOS | D2: HERCULES | E2: MS533B | G2: AUDIO | H2: 2
A3: 2 | B3: =UPPER(LEFT(C3,2)&LEFT(D3,2)&LEFT(E3,3)) -> ATHESS2 | C3: ATRILES PARLANTES | D3: HERCULES | E3: SS200BB | G3: AUDIO | H3: 8
A4: 3 | B4: =UPPER(LEFT(C4,2)&LEFT(D4,2)&LEFT(E4,3)) -> ATK&254 | C4: ATRILES MICROFONOS | D4: K&M | E4: 25400 | G4: AUDIO | H4: 10
A5: 4 | B5: =UPPER(LEFT(C5,2)&LEFT(D5,2)&LEFT(E5,3)) -> BAGATIP | C5: BASES TRUSS | D5: GALAXY | E5: TIPO CUADRADA | G5: ESTRUCTURA | H5: 2
A6: 5 | B6: =UPPER(LEFT(C6,2)&LEFT(D6,2)&LEFT(E6,3)) -> BAGEN/A | C6: BARRA T | D6: GENERICO | E6: N/A | G6: ESTRUCTURA | H6: 6
A7: 6 | B7: =UPPER(LEFT(C7,2)&LEFT(D7,2)&LEFT(E7,3)) -> BAGEN/A | C7: BASES TRUSS | D7: GENERICO | E7: N/A | G7: ESTRUCTURA | H7: 4
A8: 7 | B8: =UPPER(LEFT(C8,2)&LEFT(D8,2)&LEFT(E8,3)) -> BASA720 | C8: BARRA STROBE | D8: SANYI LIGHT | E8: 720 | G8: ILUMINACION | H8: 8
A9: 8 | B9: =UPPER(LEFT(C9,2)&LEFT(D9,2)&LEFT(E9,3)) -> BATE6X5 | C9: BARRAS PIN | D9: TECHSHOW | E9: 6X5W | G9: ILUMINACION | H9: 4
A10: 9 | B10: =UPPER(LEFT(C10,2)&LEFT(D10,2)&LEFT(E10,3)) -> BAKE6X2 | C10: BARRAS PIN | D10: KEMAX | E10: 6X20W | G10: ILUMINACION | H10: 4
A11: 10 | B11: =UPPER(LEFT(C11,2)&LEFT(D11,2)&LEFT(E11,3)) -> BIGEN/A | C11: BIOMBO | D11: GENERICO | E11: N/A | G11: ESTRUCTURA | H11: 6
A12: 11 | B12: =UPPER(LEFT(C12,2)&LEFT(D12,2)&LEFT(E12,3)) -> BOWIWIL | C12: BOLA DISCO 16" | D12: WILDPRO | E12: WILDPRO | G12: EFECTOS | H12: 20
A13: 12 | B13: =UPPER(LEFT(C13,2)&LEFT(D13,2)&LEFT(E13,3)) -> BOWIWIL | C13: BOLA DISCO 21" | D13: WILDPRO | E13: WILDPRO | G13: EFECTOS | H13: 1
A14: 13 | B14: =UPPER(LEFT(C14,2)&LEFT(D14,2)&LEFT(E14,3)) -> CAAO7R | C14: CABEZA MOVIL BEAM | D14: AOLAIT | E14: 7R | G14: ILUMINACION | H14: 8
A15: 14 | B15: =UPPER(LEFT(C15,2)&LEFT(D15,2)&LEFT(E15,3)) -> CAMO9R | C15: CABEZA MOVIL BEAM | D15: MOWL | E15: 9R | G15: ILUMINACION | H15: 10
A16: 15 | B16: =UPPER(LEFT(C16,2)&LEFT(D16,2)&LEFT(E16,3)) -> SEMOML- | C16: SEVEN EYES BACKLIGHT | D16: MOWL | E16: ML-BWJ01 | G16: ILUMINACION | H16: 2
A17: 16 | B17: =UPPER(LEFT(C17,2)&LEFT(D17,2)&LEFT(E17,3)) -> SIMOML- | C17: SIX EYES BACKLIGHT | D17: MOWL | E17: ML-XGD03 | G17: ILUMINACION | H17: 2
A18: 17 | B18: =UPPER(LEFT(C18,2)&LEFT(D18,2)&LEFT(E18,3)) -> CABASIN | C18: CAJA CABLES AUDIO | D18: BAUKER | E18: Sin Modelo | G18: AUDIO | H18: 1
A19: 18 | B19: =UPPER(LEFT(C19,2)&LEFT(D19,2)&LEFT(E19,3)) -> CABABAU | C19: CAJA CINTAS | D19: BAUKER | E19: BAUKER | G19: OTROS | H19: 1
A20: 19 | B20: =UPPER(LEFT(C20,2)&LEFT(D20,2)&LEFT(E20,3)) -> CABABAU | C20: CAJA CLAMP | D20: BAUKER | E20: BAUKER | G20: ESTRUCTURA | H20: 1
... A22: 21 | B22: =UPPER(LEFT(C22,2)&LEFT(D22,2)&LEFT(E22,3)) -> CAELSIN | C22: CAJA CONECTORES ELECTRICOS | D22: ELECTRICO | E22: Sin Modelo | G22: ENERGÍA | H22: 1
A23: 22 | B23: =UPPER(LEFT(C23,2)&LEFT(D23,2)&LEFT(E23,3)) -> CAWEWEN | C23: CAJA FUNDAS BIOMBO | D23: WENCO | E23: WENCO | G23: ESTRUCTURA | H23: 1 | AA23: /*
A24: 23 | B24: =UPPER(LEFT(C24,2)&LEFT(D24,2)&LEFT(E24,3)) -> CAWEWEN | C24: CAJA FUNDAS TRUSS | D24: WENCO | E24: WENCO | G24: ESTRUCTURA | H24: 1
A25: 24 | B25: =UPPER(LEFT(C25,2)&LEFT(D25,2)&LEFT(E25,3)) -> CAHASIN | C25: CAJA GUIRNALDAS HADAS | D25: HADAS | E25: Sin Modelo | G25: ILUMINACION | H25: 1
A26: 25 | B26: =UPPER(LEFT(C26,2)&LEFT(D26,2)&LEFT(E26,3)) -> CAGEN/A | C26: CAJA GUIRNALDAS TOSCANAS | D26: GENERICO | E26: N/A | G26: ILUMINACION | H26: 1
A27: 26 | B27: =UPPER(LEFT(C27,2)&LEFT(D27,2)&LEFT(E27,3)) -> CAPEPEL | C27: CAJA INTERLOCK | D27: PELICAN | E27: PELICAN | G27: ENERGÍA | H27: 1
A28: 27 | B28: =UPPER(LEFT(C28,2)&LEFT(D28,2)&LEFT(E28,3)) -> CAROMJ- | C28: CAJA MOTOR BOLA DISCO | D28: ROBUST | E28: MJ-5003 B | G28: EFECTOS | H28: 20
A29: 28 | B29: =UPPER(LEFT(C29,2)&LEFT(D29,2)&LEFT(E29,3)) -> CAPISIL | C29: CAJA PIVOTES | D29: PIVOTES | E29: SILVER EAGLE | G29: ESTRUCTURA | H29: 1
A30: 29 | B30: =UPPER(LEFT(C30,2)&LEFT(D30,2)&LEFT(E30,3)) -> CAWEWEN | C30: CAJA SEGURIDAD | D30: WENCO | E30: WENCO | G30: OTROS | H30: 1
A31: 30 | B31: =UPPER(LEFT(C31,2)&LEFT(D31,2)&LEFT(E31,3)) -> CAPEPEL | C31: CAJA XLR CORTOS | D31: PELICAN | E31: PELICAN | G31: ILUMINACION | H31: 1
A32: 31 | B32: =UPPER(LEFT(C32,2)&LEFT(D32,2)&LEFT(E32,3)) -> CAWEWEN | C32: CAJA ZAPATILLAS | D32: WENCO | E32: WENCO | G32: ENERGÍA | H32: 1
A33: 32 | B33: =UPPER(LEFT(C33,2)&LEFT(D33,2)&LEFT(E33,3)) -> CAPEPEL | C33: CAJA MTOUCH+NOTEBOOK | D33: PELICAN | E33: PELICAN | G33: ILUMINACION | H33: 1
A34: 33 | B34: =UPPER(LEFT(C34,2)&LEFT(D34,2)&LEFT(E34,3)) -> MTMAMTO | C34: MTOUCH | D34: MARTIN | E34: MTOUCH | G34: ILUMINACION | H34: 1
A35: 34 | B35: =UPPER(LEFT(C35,2)&LEFT(D35,2)&LEFT(E35,3)) -> CAMAMAC | C35: CABEZA MOVIL WASH | D35: MARTIN | E35: MAC AURA XB | G35: ILUMINACION | H35: 4
... A57: 56 | B57: =UPPER(LEFT(C57,2)&LEFT(D57,2)&LEFT(E57,3)) -> MAPUHF- | C57: MAQUINA HAZER | D57: PURPLE | E57: HF-900 | G57: EFECTOS | H57: 1
A58: 57 | B58: =UPPER(LEFT(C58,2)&LEFT(D58,2)&LEFT(E58,3)) -> MAMO150 | C58: MAQUINA HAZER | D58: MOWL | E58: 1500 | G58: EFECTOS | H58: 1
A59: 58 | B59: =UPPER(LEFT(C59,2)&LEFT(D59,2)&LEFT(E59,3)) -> MEK-K68 | C59: MESA SONIDO | D59: K-ACOUSTIC | E59: K68 | G59: AUDIO | H59: 1
A60: 59 | B60: =UPPER(LEFT(C60,2)&LEFT(D60,2)&LEFT(E60,3)) -> MESOEPM | C60: MESA SONIDO | D60: SOUNDCRAFT | E60: EPM6 | G60: AUDIO | H60: 2
A61: 60 | B61: =UPPER(LEFT(C61,2)&LEFT(D61,2)&LEFT(E61,3)) -> MESOSIG | C61: MESA SONIDO | D61: SOUNDCRAFT | E61: SIGNATURE 10 | G61: AUDIO | H61: 1
A62: 61 | B62: =UPPER(LEFT(C62,2)&LEFT(D62,2)&LEFT(E62,3)) -> MESOUI2 | C62: MESA SONIDO | D62: SOUNDCRAFT | E62: UI24R | G62: AUDIO | H62: 1
...

Sheet Cod_Ind
A1: Items | B1: Codigo | C1: Tipo de Equipo | D1: Marca | E1: Modelo | F1: N* Serie | G1: Categoria | H1: Cantidad unitaria | I1: Cantidad Total
A2: 1 | B2: =UPPER(LEFT(C2,2)&LEFT(D2,2)&LEFT(E2,3)&LEFT(J2)&LEFT(Cod_Gen6[[#This Row],[Cantidad unitaria]])) -> ATHEMS5-1 | C2: ATRILES MICROFONOS | D2: HERCULES | E2: MS533B | G2: AUDIO | H2: 1 | I2: 2 | J2: -
A3: 2 | B3: =UPPER(LEFT(C3,2)&LEFT(D3,2)&LEFT(E3,3)&LEFT(J3)&LEFT(Cod_Gen6[[#This Row],[Cantidad unitaria]])) -> ATHEMS5-2 | C3: ATRILES MICROFONOS | D3: HERCULES | E3: MS533B | G3: AUDIO | H3: 2 | J3: -
A4: 3 | B4: =UPPER(LEFT(C4,2)&LEFT(D4,2)&LEFT(E4,3)&LEFT(J4)&LEFT(Cod_Gen6[[#This Row],[Cantidad unitaria]])) -> ATHESS2-1 | C4: ATRILES PARLANTES | D4: HERCULES | E4: SS200BB | G4: AUDIO | H4: 1 | I4: 8 | J4: -
A5: 4 | B5: =UPPER(LEFT(C5,2)&LEFT(D5,2)&LEFT(E5,3)&LEFT(J5)&LEFT(Cod_Gen6[[#This Row],[Cantidad unitaria]])) -> ATHESS2-2 | C5: ATRILES PARLANTES | D5: HERCULES | E5: SS200BB | G5: AUDIO | H5: 2 | J5: -
A6: 5 | B6: =UPPER(LEFT(C6,2)&LEFT(D6,2)&LEFT(E6,3)&LEFT(J6)&LEFT(Cod_Gen6[[#This Row],[Cantidad unitaria]])) -> ATHESS2-3 | C6: ATRILES PARLANTES | D6: HERCULES | E6: SS200BB | G6: AUDIO | H6: 3 | J6: -
A7: 6 | B7: =UPPER(LEFT(C7,2)&LEFT(D7,2)&LEFT(E7,3)&LEFT(J7)&LEFT(Cod_Gen6[[#This Row],[Cantidad unitaria]])) -> ATHESS2-4 | C7: ATRILES PARLANTES | D7: HERCULES | E7: SS200BB | G7: AUDIO | H7: 4 | J7: -
A8: 7 | B8: =UPPER(LEFT(C8,2)&LEFT(D8,2)&LEFT(E8,3)&LEFT(J8)&LEFT(Cod_Gen6[[#This Row],[Cantidad unitaria]])) -> ATHESS2-5 | C8: ATRILES PARLANTES | D8: HERCULES | E8: SS200BB | G8: AUDIO | H8: 5 | J8: -
A9: 8 | B9: =UPPER(LEFT(C9,2)&LEFT(D9,2)&LEFT(E9,3)&LEFT(J9)&LEFT(Cod_Gen6[[#This Row],[Cantidad unitaria]])) -> ATHESS2-6 | C9: ATRILES PARLANTES | D9: HERCULES | E9: SS200BB | G9: AUDIO | H9: 6 | J9: -
A10: 9 | B10: =UPPER(LEFT(C10,2)&LEFT(D10,2)&LEFT(E10,3)&LEFT(J10)&LEFT(Cod_Gen6[[#This Row],[Cantidad unitaria]])) -> ATHESS2-7 | C10: ATRILES PARLANTES | D10: HERCULES | E10: SS200BB | G10: AUDIO | H10: 7 | J10: -
A11: 10 | B11: =UPPER(LEFT(C11,2)&LEFT(D11,2)&LEFT(E11,3)&LEFT(J11)&LEFT(Cod_Gen6[[#This Row],[Cantidad unitaria]])) -> ATHESS2-8 | C11: ATRILES PARLANTES | D11: HERCULES | E11: SS200BB | G11: AUDIO | H11: 8 | J11: -
A12: 11 | B12: =UPPER(LEFT(C12,2)&LEFT(D12,2)&LEFT(E12,3)&LEFT(J12)&LEFT(Cod_Gen6[[#This Row],[Cantidad unitaria]])) -> ATK&254-1 | C12: ATRILES MICROFONOS | D12: K&M | E12: 25400 | G12: AUDIO | H12: 1 | I12: 10 | J12: -
A13: 12 | B13: =UPPER(LEFT(C13,2)&LEFT(D13,2)&LEFT(E13,3)&LEFT(J13)&LEFT(Cod_Gen6[[#This Row],[Cantidad unitaria]])) -> ATK&254-2 | C13: ATRILES MICROFONOS | D13: K&M | E13: 25400 | G13: AUDIO | H13: 2 | J13: -
A14: 13 | B14: =UPPER(LEFT(C14,2)&LEFT(D14,2)&LEFT(E14,3)&LEFT(J14)&LEFT(Cod_Gen6[[#This Row],[Cantidad unitaria]])) -> ATK&254-3 | C14: ATRILES MICROFONOS | D14: K&M | E14: 25400 | G14: AUDIO | H14: 3 | J14: -
A15: 14 | B15: =UPPER(LEFT(C15,2)&LEFT(D15,2)&LEFT(E15,3)&LEFT(J15)&LEFT(Cod_Gen6[[#This Row],[Cantidad unitaria]])) -> ATK&254-4 | C15: ATRILES MICROFONOS | D15: K&M | E15: 25400 | G15: AUDIO | H15: 4 | J15: -
A16: 15 | B16: =UPPER(LEFT(C16,2)&LEFT(D16,2)&LEFT(E16,3)&LEFT(J16)&LEFT(Cod_Gen6[[#This Row],[Cantidad unitaria]])) -> ATK&254-5 | C16: ATRILES MICROFONOS | D16: K&M | E16: 25400 | G16: AUDIO | H16: 5 | J16: -
A17: 16 | B17: =UPPER(LEFT(C17,2)&LEFT(D17,2)&LEFT(E17,3)&LEFT(J17)&LEFT(Cod_Gen6[[#This Row],[Cantidad unitaria]])) -> ATK&254-6 | C17: ATRILES MICROFONOS | D17: K&M | E17: 25400 | G17: AUDIO | H17: 6 | J17: -
A18: 17 | B18: =UPPER(LEFT(C18,2)&LEFT(D18,2)&LEFT(E18,3)&LEFT(J18)&LEFT(Cod_Gen6[[#This Row],[Cantidad unitaria]])) -> ATK&254-7 | C18: ATRILES MICROFONOS | D18: K&M | E18: 25400 | G18: AUDIO | H18: 7 | J18: -
A19: 18 | B19: =UPPER(LEFT(C19,2)&LEFT(D19,2)&LEFT(E19,3)&LEFT(J19)&LEFT(Cod_Gen6[[#This Row],[Cantidad unitaria]])) -> ATK&254-8 | C19: ATRILES MICROFONOS | D19: K&M | E19: 25400 | G19: AUDIO | H19: 8 | J19: -
A20: 19 | B20: =UPPER(LEFT(C20,2)&LEFT(D20,2)&LEFT(E20,3)&LEFT(J20)&LEFT(Cod_Gen6[[#This Row],[Cantidad unitaria]])) -> ATK&254-9 | C20: ATRILES MICROFONOS | D20: K&M | E20: 25400 | G20: AUDIO | H20: 9 | J20: -
A21: 20 | B21: =UPPER(LEFT(C21,2)&LEFT(D21,2)&LEFT(E21,3)&LEFT(J21)&LEFT(Cod_Gen6[[#This Row],[Cantidad unitaria]],2)) -> ATK&254-10 | C21: ATRILES MICROFONOS | D21: K&M | E21: 25400 | G21: AUDIO | H21: 10 | J21: -
A22: 21 | B22: =UPPER(LEFT(C22,2)&LEFT(D22,2)&LEFT(E22,3)&LEFT(J22)&LEFT(Cod_Gen6[[#This Row],[Cantidad unitaria]],2)) -> BAGATIP-1 | C22: BASES TRUSS | D22: GALAXY | E22: TIPO CUADRADA | G22: ESTRUCTURA | H22: 1 | I22: 2 | J22: -
A23: 22 | B23: =UPPER(LEFT(C23,2)&LEFT(D23,2)&LEFT(E23,3)&LEFT(J23)&LEFT(Cod_Gen6[[#This Row],[Cantidad unitaria]],2)) -> BAGATIP-2 | C23: BASES TRUSS | D23: GALAXY | E23: TIPO CUADRADA | G23: ESTRUCTURA | H23: 2 | J23: -
A24: 23 | B24: =UPPER(LEFT(C24,2)&LEFT(D24,2)&LEFT(E24,3)&LEFT(J24)&LEFT(Cod_Gen6[[#This Row],[Cantidad unitaria]],2)) -> BAGEN/A-1 | C24: BARRA T | D24: GENERICO | E24: N/A | G24: ESTRUCTURA | H24: 1 | I24: 6 | J24: -
A25: 24 | B25: =UPPER(LEFT(C25,2)&LEFT(D25,2)&LEFT(E25,3)&LEFT(J25)&LEFT(Cod_Gen6[[#This Row],[Cantidad unitaria]],2)) -> BAGEN/A-2 | C25: BARRA T | D25: GENERICO | E25: N/A | G25: ESTRUCTURA | H25: 2 | J25: -
A26: 25 | B26: =UPPER(LEFT(C26,2)&LEFT(D26,2)&LEFT(E26,3)&LEFT(J26)&LEFT(Cod_Gen6[[#This Row],[Cantidad unitaria]],2)) -> BAGEN/A-3 | C26: BARRA T | D26: GENERICO | E26: N/A | G26: ESTRUCTURA | H26: 3 | J26: -
A27: 26 | B27: =UPPER(LEFT(C27,2)&LEFT(D27,2)&LEFT(E27,3)&LEFT(J27)&LEFT(Cod_Gen6[[#This Row],[Cantidad unitaria]],2)) -> BAGEN/A-4 | C27: BARRA T | D27: GENERICO | E27: N/A | G27: ESTRUCTURA | H27: 4 | J27: -
A28: 27 | B28: =UPPER(LEFT(C28,2)&LEFT(D28,2)&LEFT(E28,3)&LEFT(J28)&LEFT(Cod_Gen6[[#This Row],[Cantidad unitaria]],2)) -> BAGEN/A-5 | C28: BARRA T | D28: GENERICO | E28: N/A | G28: ESTRUCTURA | H28: 5 | J28: -
A29: 28 | B29: =UPPER(LEFT(C29,2)&LEFT(D29,2)&LEFT(E29,3)&LEFT(J29)&LEFT(Cod_Gen6[[#This Row],[Cantidad unitaria]],2)) -> BAGEN/A-6 | C29: BARRA T | D29: GENERICO | E29: N/A | G29: ESTRUCTURA | H29: 6 | J29: -
A30: 29 | B30: =UPPER(LEFT(C30,2)&LEFT(D30,2)&LEFT(E30,3)&LEFT(J30)&LEFT(Cod_Gen6[[#This Row],[Cantidad unitaria]],2)) -> BAGEN/A-1 | C30: BASES TRUSS | D30: GENERICO | E30: N/A | G30: ESTRUCTURA | H30: 1 | I30: 4 | J30: -
A31: 30 | B31: =UPPER(LEFT(C31,2)&LEFT(D31,2)&LEFT(E31,3)&LEFT(J31)&LEFT(Cod_Gen6[[#This Row],[Cantidad unitaria]],2)) -> BAGEN/A-2 | C31: BASES TRUSS | D31: GENERICO | E31: N/A | G31: ESTRUCTURA | H31: 2 | J31: -
A32: 31 | B32: =UPPER(LEFT(C32,2)&LEFT(D32,2)&LEFT(E32,3)&LEFT(J32)&LEFT(Cod_Gen6[[#This Row],[Cantidad unitaria]],2)) -> BAGEN/A-3 | C32: BASES TRUSS | D32: GENERICO | E32: N/A | G32: ESTRUCTURA | H32: 3 | J32: -
A33: 32 | B33: =UPPER(LEFT(C33,2)&LEFT(D33,2)&LEFT(E33,3)&LEFT(J33)&LEFT(Cod_Gen6[[#This Row],[Cantidad unitaria]],2)) -> BAGEN/A-4 | C33: BASES TRUSS | D33: GENERICO | E33: N/A | G33: ESTRUCTURA | H33: 4 | J33: -
A34: 33 | B34: =UPPER(LEFT(C34,2)&LEFT(D34,2)&LEFT(E34,3)&LEFT(J34)&LEFT(Cod_Gen6[[#This Row],[Cantidad unitaria]],2)) -> BASA720-1 | C34: BARRA STROBE | D34: SANYI LIGHT | E34: 720 | G34: ILUMINACION | H34: 1 | I34: 8 | J34: -
A35: 34 | B35: =UPPER(LEFT(C35,2)&LEFT(D35,2)&LEFT(E35,3)&LEFT(J35)&LEFT(Cod_Gen6[[#This Row],[Cantidad unitaria]],2)) -> BASA720-2 | C35: BARRA STROBE | D35: SANYI LIGHT | E35: 720 | G35: ILUMINACION | H35: 2 | J35: -
A36: 35 | B36: =UPPER(LEFT(C36,2)&LEFT(D36,2)&LEFT(E36,3)&LEFT(J36)&LEFT(Cod_Gen6[[#This Row],[Cantidad unitaria]],2)) -> BASA720-3 | C36: BARRA STROBE | D36: SANYI LIGHT | E36: 720 | G36: ILUMINACION | H36: 3 | J36: -
A37: 36 | B37: =UPPER(LEFT(C37,2)&LEFT(D37,2)&LEFT(E37,3)&LEFT(J37)&LEFT(Cod_Gen6[[#This Row],[Cantidad unitaria]],2)) -> BASA720-4 | C37: BARRA STROBE | D37: SANYI LIGHT | E37: 720 | G37: ILUMINACION | H37: 4 | J37: -
A38: 37 | B38: =UPPER(LEFT(C38,2)&LEFT(D38,2)&LEFT(E38,3)&LEFT(J38)&LEFT(Cod_Gen6[[#This Row],[Cantidad unitaria]],2)) -> BASA720-5 | C38: BARRA STROBE | D38: SANYI LIGHT | E38: 720 | G38: ILUMINACION | H38: 5 | J38: -
A39: 38 | B39: =UPPER(LEFT(C39,2)&LEFT(D39,2)&LEFT(E39,3)&LEFT(J39)&LEFT(Cod_Gen6[[#This Row],[Cantidad unitaria]],2)) -> BASA720-6 | C39: BARRA STROBE | D39: SANYI LIGHT | E39: 720 | G39: ILUMINACION | H39: 6 | J39: -
A40: 39 | B40: =UPPER(LEFT(C40,2)&LEFT(D40,2)&LEFT(E40,3)&LEFT(J40)&LEFT(Cod_Gen6[[#This Row],[Cantidad unitaria]],2)) -> BASA720-7 | C40: BARRA STROBE | D40: SANYI LIGHT | E40: 720 | G40: ILUMINACION | H40: 7 | J40: -
...

Sheet Inventario
A1: Items | B1: Cod_Producto | C1: Tipo de Equipo | D1: Marca | E1: Modelo | F1: N* Serie | G1: Estado | H1: Observacion
A2: 1 | B2: =Cod_Gen6[[#This Row],[Codigo]] -> ATHEMS5-1 | C2: =Cod_Gen6[[#This Row],[Tipo de Equipo]] -> ATRILES MICROFONOS | D2: =Cod_Gen6[[#This Row],[Marca]] -> HERCULES | E2: =Cod_Gen6[[#This Row],[Modelo]] -> MS533B | F2: =Cod_Gen6[[#This Row],[N* Serie]] -> 0
A3: 2 | B3: =Cod_Gen6[[#This Row],[Codigo]] -> ATHEMS5-2 | C3: =Cod_Gen6[[#This Row],[Tipo de Equipo]] -> ATRILES MICROFONOS | D3: =Cod_Gen6[[#This Row],[Marca]] -> HERCULES | E3: =Cod_Gen6[[#This Row],[Modelo]] -> MS533B | F3: =Cod_Gen6[[#This Row],[N* Serie]] -> 0
A4: 3 | B4: =Cod_Gen6[[#This Row],[Codigo]] -> ATHESS2-1 | C4: =Cod_Gen6[[#This Row],[Tipo de Equipo]] -> ATRILES PARLANTES | D4: =Cod_Gen6[[#This Row],[Marca]] -> HERCULES | E4: =Cod_Gen6[[#This Row],[Modelo]] -> SS200BB | F4: =Cod_Gen6[[#This Row],[N* Serie]] -> 0
A5: 4 | B5: =Cod_Gen6[[#This Row],[Codigo]] -> ATHESS2-2 | C5: =Cod_Gen6[[#This Row],[Tipo de Equipo]] -> ATRILES PARLANTES | D5: =Cod_Gen6[[#This Row],[Marca]] -> HERCULES | E5: =Cod_Gen6[[#This Row],[Modelo]] -> SS200BB | F5: =Cod_Gen6[[#This Row],[N* Serie]] -> 0
A6: 5 | B6: =Cod_Gen6[[#This Row],[Codigo]] -> ATHESS2-3 | C6: =Cod_Gen6[[#This Row],[Tipo de Equipo]] -> ATRILES PARLANTES | D6: =Cod_Gen6[[#This Row],[Marca]] -> HERCULES | E6: =Cod_Gen6[[#This Row],[Modelo]] -> SS200BB | F6: =Cod_Gen6[[#This Row],[N* Serie]] -> 0
A7: 6 | B7: =Cod_Gen6[[#This Row],[Codigo]] -> ATHESS2-4 | C7: =Cod_Gen6[[#This Row],[Tipo de Equipo]] -> ATRILES PARLANTES | D7: =Cod_Gen6[[#This Row],[Marca]] -> HERCULES | E7: =Cod_Gen6[[#This Row],[Modelo]] -> SS200BB | F7: =Cod_Gen6[[#This Row],[N* Serie]] -> 0
A8: 7 | B8: =Cod_Gen6[[#This Row],[Codigo]] -> ATHESS2-5 | C8: =Cod_Gen6[[#This Row],[Tipo de Equipo]] -> ATRILES PARLANTES | D8: =Cod_Gen6[[#This Row],[Marca]] -> HERCULES | E8: =Cod_Gen6[[#This Row],[Modelo]] -> SS200BB | F8: =Cod_Gen6[[#This Row],[N* Serie]] -> 0
A9: 8 | B9: =Cod_Gen6[[#This Row],[Codigo]] -> ATHESS2-6 | C9: =Cod_Gen6[[#This Row],[Tipo de Equipo]] -> ATRILES PARLANTES | D9: =Cod_Gen6[[#This Row],[Marca]] -> HERCULES | E9: =Cod_Gen6[[#This Row],[Modelo]] -> SS200BB | F9: =Cod_Gen6[[#This Row],[N* Serie]] -> 0
A10: 9 | B10: =Cod_Gen6[[#This Row],[Codigo]] -> ATHESS2-7 | C10: =Cod_Gen6[[#This Row],[Tipo de Equipo]] -> ATRILES PARLANTES | D10: =Cod_Gen6[[#This Row],[Marca]] -> HERCULES | E10: =Cod_Gen6[[#This Row],[Modelo]] -> SS200BB | F10: =Cod_Gen6[[#This Row],[N* Serie]] -> 0
A11: 10 | B11: =Cod_Gen6[[#This Row],[Codigo]] -> ATHESS2-8 | C11: =Cod_Gen6[[#This Row],[Tipo de Equipo]] -> ATRILES PARLANTES | D11: =Cod_Gen6[[#This Row],[Marca]] -> HERCULES | E11: =Cod_Gen6[[#This Row],[Modelo]] -> SS200BB | F11: =Cod_Gen6[[#This Row],[N* Serie]] -> 0
A12: 11 | B12: =Cod_Gen6[[#This Row],[Codigo]] -> ATK&254-1 | C12: =Cod_Gen6[[#This Row],[Tipo de Equipo]] -> ATRILES MICROFONOS | D12: =Cod_Gen6[[#This Row],[Marca]] -> K&M | E12: =Cod_Gen6[[#This Row],[Modelo]] -> 25400 | F12: =Cod_Gen6[[#This Row],[N* Serie]] -> 0
A13: 12 | B13: =Cod_Gen6[[#This Row],[Codigo]] -> ATK&254-2 | C13: =Cod_Gen6[[#This Row],[Tipo de Equipo]] -> ATRILES MICROFONOS | D13: =Cod_Gen6[[#This Row],[Marca]] -> K&M | E13: =Cod_Gen6[[#This Row],[Modelo]] -> 25400 | F13: =Cod_Gen6[[#This Row],[N* Serie]] -> 0
... A320: 319 | B320: =Cod_Gen6[[#This Row],[Codigo]] -> TUGEN/A-7 | C320: =Cod_Gen6[[#This Row],[Tipo de Equipo]] -> TUBO 3 MTS | D320: =Cod_Gen6[[#This Row],[Marca]] -> GENERICO | E320: =Cod_Gen6[[#This Row],[Modelo]] -> N/A | F320: =Cod_Gen6[[#This Row],[N* Serie]] -> 0

Sheet Registro_Histo
A1: Salida Almacen | B1: Hora Salida | C1: Codigo Producto | D1: Cantidad | E1: Producto | F1: Marca | G1: Modelo | H1: N° Serie | I1: Ubicación Actual | J1: Responsable | K1: Obs.Salida | L1: Retorno | M1: Dias desde Salida | N1: Advertencia
A2: ='Scan to Sheets'!A2 -> 0 | B2: ='Scan to Sheets'!B2 -> 0 | C2: ='Scan to Sheets'!C2 -> 0 | D2: ='Scan to Sheets'!D2 -> 0 | E2: =IFERROR(VLOOKUP(C2,#REF!, 2, FALSE), "NO ENCONTRADO") -> NO ENCONTRADO | F2: =IFERROR(VLOOKUP(C2,#REF!, 3, FALSE), "NO ENCONTRADO") -> NO ENCONTRADO | G2: =IFERROR(VLOOKUP(C2,#REF!, 4, FALSE), "NO ENCONTRADO") -> NO ENCONTRADO | H2: =IFERROR(VLOOKUP(C2,#REF!, 5, FALSE), "NO ENCONTRADO") -> NO ENCONTRADO | M2: =TODAY()-A2 -> 46026 | N2: =IF(AND(L2="No",M2>= 1),"⚠️ATRASADO","✅") -> ✅
A3: ='Scan to Sheets'!A3 -> 0 | B3: ='Scan to Sheets'!B3 -> 0 | C3: ='Scan to Sheets'!C3 -> 0 | D3: ='Scan to Sheets'!D3 -> 0 | E3: =IFERROR(VLOOKUP(C3,#REF!, 2, FALSE), "NO ENCONTRADO") -> NO ENCONTRADO | F3: =IFERROR(VLOOKUP(C3,#REF!, 3, FALSE), "NO ENCONTRADO") -> NO ENCONTRADO | G3: =IFERROR(VLOOKUP(C3,#REF!, 4, FALSE), "NO ENCONTRADO") -> NO ENCONTRADO | H3: =IFERROR(VLOOKUP(C3,#REF!, 5, FALSE), "NO ENCONTRADO") -> NO ENCONTRADO | M3: =TODAY()-A3 -> 46026 | N3: =IF(AND(L3="No",M3>= 1),"⚠️ATRASADO","✅") -> ✅
A4: ='Scan to Sheets'!A4 -> 0 | B4: ='Scan to Sheets'!B4 -> 0 | C4: ='Scan to Sheets'!C4 -> 0 | D4: ='Scan to Sheets'!D4 -> 0 | E4: =IFERROR(VLOOKUP(C4,#REF!, 2, FALSE), "NO ENCONTRADO") -> NO ENCONTRADO | F4: =IFERROR(VLOOKUP(C4,#REF!, 3, FALSE), "NO ENCONTRADO") -> NO ENCONTRADO | G4: =IFERROR(VLOOKUP(C4,#REF!, 4, FALSE), "NO ENCONTRADO") -> NO ENCONTRADO | H4: =IFERROR(VLOOKUP(C4,#REF!, 5, FALSE), "NO ENCONTRADO") -> NO ENCONTRADO | M4: =TODAY()-A4 -> 46026 | N4: =IF(AND(L4="No",M4>= 1),"⚠️ATRASADO","✅") -> ✅
A5: ='Scan to Sheets'!A5 -> 0 | B5: ='Scan to Sheets'!B5 -> 0 | C5: ='Scan to Sheets'!C5 -> 0 | D5: ='Scan to Sheets'!D5 -> 0 | E5: =IFERROR(VLOOKUP(C5,#REF!, 2, FALSE), "NO ENCONTRADO") -> NO ENCONTRADO | F5: =IFERROR(VLOOKUP(C5,#REF!, 3, FALSE), "NO ENCONTRADO") -> NO ENCONTRADO | G5: =IFERROR(VLOOKUP(C5,#REF!, 4, FALSE), "NO ENCONTRADO") -> NO ENCONTRADO | H5: =IFERROR(VLOOKUP(C5,#REF!, 5, FALSE), "NO ENCONTRADO") -> NO ENCONTRADO | M5: =TODAY()-A5 -> 46026 | N5: =IF(AND(L5="No",M5>= 1),"⚠️ATRASADO","✅") -> ✅
A6: ='Scan to Sheets'!A6 -> 0 | B6: ='Scan to Sheets'!B6 -> 0 | C6: ='Scan to Sheets'!C6 -> 0 | D6: ='Scan to Sheets'!D6 -> 0 | E6: =IFERROR(VLOOKUP(C6,#REF!, 2, FALSE), "NO ENCONTRADO") -> NO ENCONTRADO | F6: =IFERROR(VLOOKUP(C6,#REF!, 3, FALSE), "NO ENCONTRADO") -> NO ENCONTRADO | G6: =IFERROR(VLOOKUP(C6,#REF!, 4, FALSE), "NO ENCONTRADO") -> NO ENCONTRADO | H6: =IFERROR(VLOOKUP(C6,#REF!, 5, FALSE), "NO ENCONTRADO") -> NO ENCONTRADO | M6: =TODAY()-A6 -> 46026 | N6: =IF(AND(L6="No",M6>= 1),"⚠️ATRASADO","✅") -> ✅
A7: ='Scan to Sheets'!A7 -> 0 | B7: ='Scan to Sheets'!B7 -> 0 | C7: ='Scan to Sheets'!C7 -> 0 | D7: ='Scan to Sheets'!D7 -> 0 | E7: =IFERROR(VLOOKUP(C7,#REF!, 2, FALSE), "NO ENCONTRADO") -> NO ENCONTRADO | F7: =IFERROR(VLOOKUP(C7,#REF!, 3, FALSE), "NO ENCONTRADO") -> NO ENCONTRADO | G7: =IFERROR(VLOOKUP(C7,#REF!, 4, FALSE), "NO ENCONTRADO") -> NO ENCONTRADO | H7: =IFERROR(VLOOKUP(C7,#REF!, 5, FALSE), "NO ENCONTRADO") -> NO ENCONTRADO | M7: =TODAY()-A7 -> 46026 | N7: =IF(AND(L7="No",M7>= 1),"⚠️ATRASADO","✅") -> ✅
A8: ='Scan to Sheets'!A8 -> 0 | B8: ='Scan to Sheets'!B8 -> 0 | C8: ='Scan to Sheets'!C8 -> 0 | D8: ='Scan to Sheets'!D8 -> 0 | E8: =IFERROR(VLOOKUP(C8,#REF!, 2, FALSE), "NO ENCONTRADO") -> NO ENCONTRADO | F8: =IFERROR(VLOOKUP(C8,#REF!, 3, FALSE), "NO ENCONTRADO") -> NO ENCONTRADO | G8: =IFERROR(VLOOKUP(C8,#REF!, 4, FALSE), "NO ENCONTRADO") -> NO ENCONTRADO | H8: =IFERROR(VLOOKUP(C8,#REF!, 5, FALSE), "NO ENCONTRADO") -> NO ENCONTRADO | M8: =TODAY()-A8 -> 46026 | N8: =IF(AND(L8="No",M8>= 1),"⚠️ATRASADO","✅") -> ✅
A9: ='Scan to Sheets'!A9 -> 0 | B9: ='Scan to Sheets'!B9 -> 0 | C9: ='Scan to Sheets'!C9 -> 0 | D9: ='Scan to Sheets'!D9 -> 0 | E9: =IFERROR(VLOOKUP(C9,#REF!, 2, FALSE), "NO ENCONTRADO") -> NO ENCONTRADO | F9: =IFERROR(VLOOKUP(C9,#REF!, 3, FALSE), "NO ENCONTRADO") -> NO ENCONTRADO | G9: =IFERROR(VLOOKUP(C9,#REF!, 4, FALSE), "NO ENCONTRADO") -> NO ENCONTRADO | H9: =IFERROR(VLOOKUP(C9,#REF!, 5, FALSE), "NO ENCONTRADO") -> NO ENCONTRADO | M9: =TODAY()-A9 -> 46026 | N9: =IF(AND(L9="No",M9>= 1),"⚠️ATRASADO","✅") -> ✅
A10: ='Scan to Sheets'!A10 -> 0 | B10: ='Scan to Sheets'!B10 -> 0 | C10: ='Scan to Sheets'!C10 -> 0 | D10: ='Scan to Sheets'!D10 -> 0 | E10: =IFERROR(VLOOKUP(C10,#REF!, 2, FALSE), "NO ENCONTRADO") -> NO ENCONTRADO | F10: =IFERROR(VLOOKUP(C10,#REF!, 3, FALSE), "NO ENCONTRADO") -> NO ENCONTRADO | G10: =IFERROR(VLOOKUP(C10,#REF!, 4, FALSE), "NO ENCONTRADO") -> NO ENCONTRADO | H10: =IFERROR(VLOOKUP(C10,#REF!, 5, FALSE), "NO ENCONTRADO") -> NO ENCONTRADO | M10: =TODAY()-A10 -> 46026 | N10: =IF(AND(L10="No",M10>= 1),"⚠️ATRASADO","✅") -> ✅
A11: ='Scan to Sheets'!A11 -> 0 | B11: ='Scan to Sheets'!B11 -> 0 | C11: ='Scan to Sheets'!C11 -> 0 | D11: ='Scan to Sheets'!D11 -> 0 | E11: =IFERROR(VLOOKUP(C11,#REF!, 2, FALSE), "NO ENCONTRADO") -> NO ENCONTRADO | F11: =IFERROR(VLOOKUP(C11,#REF!, 3, FALSE), "NO ENCONTRADO") -> NO ENCONTRADO | G11: =IFERROR(VLOOKUP(C11,#REF!, 4, FALSE), "NO ENCONTRADO") -> NO ENCONTRADO | H11: =IFERROR(VLOOKUP(C11,#REF!, 5, FALSE), "NO ENCONTRADO") -> NO ENCONTRADO | M11: =TODAY()-A11 -> 46026 | N11: =IF(AND(L11="No",M11>= 1),"⚠️ATRASADO","✅") -> ✅
A12: ='Scan to Sheets'!A12 -> 0 | B12: ='Scan to Sheets'!B12 -> 0 | C12: ='Scan to Sheets'!C12 -> 0 | D12: ='Scan to Sheets'!D12 -> 0 | E12: =IFERROR(VLOOKUP(C12,#REF!, 2, FALSE), "NO ENCONTRADO") -> NO ENCONTRADO | F12: =IFERROR(VLOOKUP(C12,#REF!, 3, FALSE), "NO ENCONTRADO") -> NO ENCONTRADO | G12: =IFERROR(VLOOKUP(C12,#REF!, 4, FALSE), "NO ENCONTRADO") -> NO ENCONTRADO | H12: =IFERROR(VLOOKUP(C12,#REF!, 5, FALSE), "NO ENCONTRADO") -> NO ENCONTRADO | M12: =TODAY()-A12 -> 46026 | N12: =IF(AND(L12="No",M12>= 1),"⚠️ATRASADO","✅") -> ✅
A13: ='Scan to Sheets'!A13 -> 0 | B13: ='Scan to Sheets'!B13 -> 0 | C13: ='Scan to Sheets'!C13 -> 0 | D13: ='Scan to Sheets'!D13 -> 0 | E13: =IFERROR(VLOOKUP(C13,#REF!, 2, FALSE), "NO ENCONTRADO") -> NO ENCONTRADO | F13: =IFERROR(VLOOKUP(C13,#REF!, 3, FALSE), "NO ENCONTRADO") -> NO ENCONTRADO | G13: =IFERROR(VLOOKUP(C13,#REF!, 4, FALSE), "NO ENCONTRADO") -> NO ENCONTRADO | H13: =IFERROR(VLOOKUP(C13,#REF!, 5, FALSE), "NO ENCONTRADO") -> NO ENCONTRADO | M13: =TODAY()-A13 -> 46026 | N13: =IF(AND(L13="No",M13>= 1),"⚠️ATRASADO","✅") -> ✅
... A903: ='Scan to Sheets'!A903 -> 0 | B903: ='Scan to Sheets'!B903 -> 0 | C903: ='Scan to Sheets'!C903 -> 0 | D903: ='Scan to Sheets'!D903 -> 0 | E903: =IFERROR(VLOOKUP(C903,#REF!, 2, FALSE), "NO ENCONTRADO") -> NO ENCONTRADO | F903: =IFERROR(VLOOKUP(C903,#REF!, 3, FALSE), "NO ENCONTRADO") -> NO ENCONTRADO | G903: =IFERROR(VLOOKUP(C903,#REF!, 4, FALSE), "NO ENCONTRADO") -> NO ENCONTRADO | H903: =IFERROR(VLOOKUP(C903,#REF!, 5, FALSE), "NO ENCONTRADO") -> NO ENCONTRADO | M903: =TODAY()-A903 -> 46026 | N903: =IF(AND(L903="No",M903>= 1),"⚠️ATRASADO","✅") -> ✅

Sheet Inv_Clasif
A1: Inventario Clasificado
A2: Tipo de Equipo | B2: Marca | C2: Cod_Producto | D2: Modelo | E2: N* Serie | F2: Estado | G2: Observacion
A3: ATRILES MICROFONOS
A4: ATRILES PARLANTES
A5: BARRA STROBE
A6: BARRA T
A7: BARRAS PIN
A8: BASES TRUSS
A9: BIOMBO
A10: BOLA DISCO 16" | B10: WILDPRO | C10: BOWIWIL-1 | D10: WILDPRO | E10: 0 | F10: (en blanco) | G10: (en blanco)
C11: BOWIWIL-10 | D11: WILDPRO | E11: 0 | F11: (en blanco) | G11: (en blanco)
C12: BOWIWIL-11 | D12: WILDPRO | E12: 0 | F12: (en blanco) | G12: (en blanco)
C13: BOWIWIL-12 | D13: WILDPRO | E13: 0 | F13: (en blanco) | G13: (en blanco)
C14: BOWIWIL-13 | D14: WILDPRO | E14: 0 | F14: (en blanco) | G14: (en blanco)
C15: BOWIWIL-14 | D15: WILDPRO | E15: 0 | F15: (en blanco) | G15: (en blanco)
C16: BOWIWIL-15 | D16: WILDPRO | E16: 0 | F16: (en blanco) | G16: (en blanco)
C17: BOWIWIL-16 | D17: WILDPRO | E17: 0 | F17: (en blanco) | G17: (en blanco)
C18: BOWIWIL-17 | D18: WILDPRO | E18: 0 | F18: (en blanco) | G18: (en blanco)
C19: BOWIWIL-18 | D19: WILDPRO | E19: 0 | F19: (en blanco) | G19: (en blanco)
C20: BOWIWIL-19 | D20: WILDPRO | E20: 0 | F20: (en blanco) | G20: (en blanco)
C21: BOWIWIL-2 | D21: WILDPRO | E21: 0 | F21: (en blanco) | G21: (en blanco)
C22: BOWIWIL-20 | D22: WILDPRO | E22: 0 | F22: (en blanco) | G22: (en blanco)
... C29: BOWIWIL-9 | D29: WILDPRO | E29: 0 | F29: (en blanco) | G29: (en blanco)
A30: BOLA DISCO 21" | B30: WILDPRO | C30: BOWIWIL-1 | D30: WILDPRO | E30: 0 | F30: (en blanco) | G30: (en blanco)
A31: CABEZA MOVIL BEAM
A32: CABEZA MOVIL SPOT
A33: CABEZA MOVIL WASH
A34: CAJA BORDES PISTA DE BAILE
A35: CAJA CABLES AUDIO
A36: CAJA CINTAS
A37: CAJA CLAMP
A38: CAJA CONECTORES AUDIO
A39: CAJA CONECTORES ELECTRICOS
A40: CAJA CONSOLA DMX
A41: CAJA FUNDAS BIOMBO
A42: CAJA FUNDAS TRUSS
... A46: CAJA MOTOR BOLA DISCO
A47: CAJA MTOUCH+NOTEBOOK | B47: PELICAN | C47: CAPEPEL-1 | D47: PELICAN | E47: 0 | F47: (en blanco) | G47: (en blanco)
A48: CAJA PIVOTES
A49: CAJA SEGURIDAD
...

Sheet Estadisticas
A1: Escaneo_Productos | D1: Estado_Productos
A2: Codigo | B2: Veces | D2: Estado | E2: Cantidad
A3: ATHEMS-01 | B3: =COUNTIF('Scan to Sheets'!$C$2:$C$825,A3) -> 0 | D3: Disponible | E3: =COUNTIF(Gestion_Inventario[Estado],D3) -> 0
A4: ATHEMS-02 | B4: =COUNTIF('Scan to Sheets'!$C$2:$C$825,A4) -> 0 | D4: En reparacion | E4: =COUNTIF(Gestion_Inventario[Estado],D4) -> 0
A5: ATK&25-01 | B5: =COUNTIF('Scan to Sheets'!$C$2:$C$825,A5) -> 0 | D5: Dañado | E5: =COUNTIF(Gestion_Inventario[Estado],D5) -> 0
A6: ATK&25-02 | B6: =COUNTIF('Scan to Sheets'!$C$2:$C$825,A6) -> 0
A7: ATK&25-03 | B7: =COUNTIF('Scan to Sheets'!$C$2:$C$825,A7) -> 0 | D7: Ubicacion Actual
A8: ATK&25-04 | B8: =COUNTIF('Scan to Sheets'!$C$2:$C$825,A8) -> 0 | D8: Estado | E8: Cantidad
A9: ATK&25-05 | B9: =COUNTIF('Scan to Sheets'!$C$2:$C$825,A9) -> 0 | D9: Saliendo Bodega | E9: =COUNTIF(Registro_Historial[Ubicación Actual],D9) -> 0
A10: ATK&25-06 | B10: =COUNTIF('Scan to Sheets'!$C$2:$C$825,A10) -> 0 | D10: En Evento | E10: =COUNTIF(Registro_Historial[Ubicación Actual],D10) -> 0
A11: ATK&25-07 | B11: =COUNTIF('Scan to Sheets'!$C$2:$C$825,A11) -> 0
A12: ATK&25-08 | B12: =COUNTIF('Scan to Sheets'!$C$2:$C$825,A12) -> 0
A13: ATK&25-09 | B13: =COUNTIF('Scan to Sheets'!$C$2:$C$825,A13) -> 0
A14: ATK&25-10 | B14: =COUNTIF('Scan to Sheets'!$C$2:$C$825,A14) -> 0
A15: ATHESS-01 | B15: =COUNTIF('Scan to Sheets'!$C$2:$C$825,A15) -> 0
A16: ATHESS-02 | B16: =COUNTIF('Scan to Sheets'!$C$2:$C$825,A16) -> 0
A17: ATHESS-03 | B17: =COUNTIF('Scan to Sheets'!$C$2:$C$825,A17) -> 0
A18: ATHESS-04 | B18: =COUNTIF('Scan to Sheets'!$C$2:$C$825,A18) -> 0
A19: ATHESS-05 | B19: =COUNTIF('Scan to Sheets'!$C$2:$C$825,A19) -> 0
A20: ATHESS-06 | B20: =COUNTIF('Scan to Sheets'!$C$2:$C$825,A20) -> 0
A21: ATHESS-07 | B21: =COUNTIF('Scan to Sheets'!$C$2:$C$825,A21) -> 0
A22: ATHESS-08 | B22: =COUNTIF('Scan to Sheets'!$C$2:$C$825,A22) -> 0
... A284: TUGESI-07 | B284: =COUNTIF('Scan to Sheets'!$C$2:$C$825,A284) -> 0
